telegram.ext.dispatcher - ERROR - An uncaught error was raised while processing the update
Traceback (most recent call last):
  File "C:\Python34\lib\site-packages\telegram\ext\dispatcher.py", line 279, in process_update
    handler.handle_update(update, self)
  File "C:\Python34\lib\site-packages\telegram\ext\commandhandler.py", line 173, in handle_update
    return self.callback(dispatcher.bot, update, **optional_args)
  File "calc.py", line 72, in calc
    bot.send_message(chat_id=chat_id, text="Custom Keyboard Test", reply_markup=reply_markup)
NameError: name 'chat_id' is not defined
telegram.ext.updater - INFO - Received signal 2 (SIGINT), stopping...
telegram.ext.updater - WARNING - Exiting immediately!
telegram.ext.dispatcher - ERROR - An uncaught error was raised while processing the update
Traceback (most recent call last):
  File "C:\Python34\lib\site-packages\telegram\ext\dispatcher.py", line 279, in process_update
    handler.handle_update(update, self)
  File "C:\Python34\lib\site-packages\telegram\ext\commandhandler.py", line 173, in handle_update
    return self.callback(dispatcher.bot, update, **optional_args)
  File "calc.py", line 28, in ask_planet
    planet_constellation(bot,update)
  File "calc.py", line 52, in planet_constellation
    update.message.reply_text('Планета '+p_planet+' находится в созвездии '+ret[1])
UnboundLocalError: local variable 'ret' referenced before assignment
telegram.ext.dispatcher - ERROR - An uncaught error was raised while processing the update
Traceback (most recent call last):
  File "C:\Python34\lib\site-packages\telegram\ext\dispatcher.py", line 279, in process_update
    handler.handle_update(update, self)
  File "C:\Python34\lib\site-packages\telegram\ext\commandhandler.py", line 173, in handle_update
    return self.callback(dispatcher.bot, update, **optional_args)
  File "calc.py", line 28, in ask_planet
    planet_constellation(bot,update)
  File "calc.py", line 52, in planet_constellation
    update.message.reply_text('Планета '+p_planet+' находится в созвездии '+ret[1])
UnboundLocalError: local variable 'ret' referenced before assignment
telegram.ext.dispatcher - ERROR - An uncaught error was raised while processing the update
Traceback (most recent call last):
  File "C:\Python34\lib\site-packages\telegram\ext\dispatcher.py", line 279, in process_update
    handler.handle_update(update, self)
  File "C:\Python34\lib\site-packages\telegram\ext\messagehandler.py", line 169, in handle_update
    return self.callback(dispatcher.bot, update, **optional_args)
  File "calc.py", line 48, in planet_constellation
    ret=ephem.constellation(ephem.Earth(datetime.datetime.now()))
AttributeError: 'module' object has no attribute 'Earth'
telegram.ext.dispatcher - ERROR - An uncaught error was raised while processing the update
Traceback (most recent call last):
  File "C:\Python34\lib\site-packages\telegram\ext\dispatcher.py", line 279, in process_update
    handler.handle_update(update, self)
  File "C:\Python34\lib\site-packages\telegram\ext\commandhandler.py", line 173, in handle_update
    return self.callback(dispatcher.bot, update, **optional_args)
  File "calc.py", line 87, in calc
    update.message.reply_text("Результат: "+str(val))
UnboundLocalError: local variable 'val' referenced before assignment
telegram.ext.updater - ERROR - Error while getting Updates: urllib3 HTTPError ('Connection aborted.', ConnectionResetError(10054, 'Удаленный хост принудительно разорвал существующее подключение', None, 10054, None))
telegram.vendor.ptb_urllib3.urllib3.connectionpool - WARNING - Retrying (Retry(total=2, connect=None, read=None, redirect=None)) after connection broken by 'NewConnectionError('<telegram.vendor.ptb_urllib3.urllib3.contrib.socks.SOCKSHTTPSConnection object at 0x00000000035CCDD8>: Failed to establish a new connection: [Errno 11001] getaddrinfo failed',)': /bot596268584:AAEbS5S8eJYm3ksbBy3fluXIrgifedC23lg/getUpdates
telegram.vendor.ptb_urllib3.urllib3.connectionpool - WARNING - Retrying (Retry(total=1, connect=None, read=None, redirect=None)) after connection broken by 'NewConnectionError('<telegram.vendor.ptb_urllib3.urllib3.contrib.socks.SOCKSHTTPSConnection object at 0x00000000035CC630>: Failed to establish a new connection: [Errno 11001] getaddrinfo failed',)': /bot596268584:AAEbS5S8eJYm3ksbBy3fluXIrgifedC23lg/getUpdates
telegram.vendor.ptb_urllib3.urllib3.connectionpool - WARNING - Retrying (Retry(total=0, connect=None, read=None, redirect=None)) after connection broken by 'NewConnectionError('<telegram.vendor.ptb_urllib3.urllib3.contrib.socks.SOCKSHTTPSConnection object at 0x00000000035CCF60>: Failed to establish a new connection: [Errno 11001] getaddrinfo failed',)': /bot596268584:AAEbS5S8eJYm3ksbBy3fluXIrgifedC23lg/getUpdates
telegram.ext.updater - ERROR - Error while getting Updates: urllib3 HTTPError SOCKSHTTPSConnectionPool(host='api.telegram.org', port=443): Max retries exceeded with url: /bot596268584:AAEbS5S8eJYm3ksbBy3fluXIrgifedC23lg/getUpdates (Caused by NewConnectionError('<telegram.vendor.ptb_urllib3.urllib3.contrib.socks.SOCKSHTTPSConnection object at 0x00000000051564E0>: Failed to establish a new connection: [Errno 11001] getaddrinfo failed',))
telegram.vendor.ptb_urllib3.urllib3.connectionpool - WARNING - Retrying (Retry(total=2, connect=None, read=None, redirect=None)) after connection broken by 'NewConnectionError('<telegram.vendor.ptb_urllib3.urllib3.contrib.socks.SOCKSHTTPSConnection object at 0x0000000005156D68>: Failed to establish a new connection: [Errno 11001] getaddrinfo failed',)': /bot596268584:AAEbS5S8eJYm3ksbBy3fluXIrgifedC23lg/getUpdates
telegram.vendor.ptb_urllib3.urllib3.connectionpool - WARNING - Retrying (Retry(total=1, connect=None, read=None, redirect=None)) after connection broken by 'NewConnectionError('<telegram.vendor.ptb_urllib3.urllib3.contrib.socks.SOCKSHTTPSConnection object at 0x00000000051569B0>: Failed to establish a new connection: [Errno 11001] getaddrinfo failed',)': /bot596268584:AAEbS5S8eJYm3ksbBy3fluXIrgifedC23lg/getUpdates
telegram.vendor.ptb_urllib3.urllib3.connectionpool - WARNING - Retrying (Retry(total=0, connect=None, read=None, redirect=None)) after connection broken by 'NewConnectionError('<telegram.vendor.ptb_urllib3.urllib3.contrib.socks.SOCKSHTTPSConnection object at 0x0000000005156240>: Failed to establish a new connection: [Errno 11001] getaddrinfo failed',)': /bot596268584:AAEbS5S8eJYm3ksbBy3fluXIrgifedC23lg/getUpdates
telegram.ext.updater - ERROR - Error while getting Updates: urllib3 HTTPError SOCKSHTTPSConnectionPool(host='api.telegram.org', port=443): Max retries exceeded with url: /bot596268584:AAEbS5S8eJYm3ksbBy3fluXIrgifedC23lg/getUpdates (Caused by NewConnectionError('<telegram.vendor.ptb_urllib3.urllib3.contrib.socks.SOCKSHTTPSConnection object at 0x0000000005156C88>: Failed to establish a new connection: [Errno 11001] getaddrinfo failed',))
telegram.vendor.ptb_urllib3.urllib3.connectionpool - WARNING - Retrying (Retry(total=2, connect=None, read=None, redirect=None)) after connection broken by 'NewConnectionError('<telegram.vendor.ptb_urllib3.urllib3.contrib.socks.SOCKSHTTPSConnection object at 0x00000000051562B0>: Failed to establish a new connection: [Errno 11001] getaddrinfo failed',)': /bot596268584:AAEbS5S8eJYm3ksbBy3fluXIrgifedC23lg/getUpdates
telegram.vendor.ptb_urllib3.urllib3.connectionpool - WARNING - Retrying (Retry(total=1, connect=None, read=None, redirect=None)) after connection broken by 'NewConnectionError('<telegram.vendor.ptb_urllib3.urllib3.contrib.socks.SOCKSHTTPSConnection object at 0x0000000005156EF0>: Failed to establish a new connection: [Errno 11001] getaddrinfo failed',)': /bot596268584:AAEbS5S8eJYm3ksbBy3fluXIrgifedC23lg/getUpdates
telegram.vendor.ptb_urllib3.urllib3.connectionpool - WARNING - Retrying (Retry(total=0, connect=None, read=None, redirect=None)) after connection broken by 'NewConnectionError('<telegram.vendor.ptb_urllib3.urllib3.contrib.socks.SOCKSHTTPSConnection object at 0x00000000051562E8>: Failed to establish a new connection: [Errno 11001] getaddrinfo failed',)': /bot596268584:AAEbS5S8eJYm3ksbBy3fluXIrgifedC23lg/getUpdates
telegram.ext.updater - ERROR - Error while getting Updates: urllib3 HTTPError SOCKSHTTPSConnectionPool(host='api.telegram.org', port=443): Max retries exceeded with url: /bot596268584:AAEbS5S8eJYm3ksbBy3fluXIrgifedC23lg/getUpdates (Caused by NewConnectionError('<telegram.vendor.ptb_urllib3.urllib3.contrib.socks.SOCKSHTTPSConnection object at 0x0000000005156B70>: Failed to establish a new connection: [Errno 11001] getaddrinfo failed',))
telegram.vendor.ptb_urllib3.urllib3.connectionpool - WARNING - Retrying (Retry(total=2, connect=None, read=None, redirect=None)) after connection broken by 'NewConnectionError('<telegram.vendor.ptb_urllib3.urllib3.contrib.socks.SOCKSHTTPSConnection object at 0x0000000005156FD0>: Failed to establish a new connection: [Errno 11001] getaddrinfo failed',)': /bot596268584:AAEbS5S8eJYm3ksbBy3fluXIrgifedC23lg/getUpdates
telegram.vendor.ptb_urllib3.urllib3.connectionpool - WARNING - Retrying (Retry(total=1, connect=None, read=None, redirect=None)) after connection broken by 'NewConnectionError('<telegram.vendor.ptb_urllib3.urllib3.contrib.socks.SOCKSHTTPSConnection object at 0x00000000035A7EB8>: Failed to establish a new connection: [Errno 11001] getaddrinfo failed',)': /bot596268584:AAEbS5S8eJYm3ksbBy3fluXIrgifedC23lg/getUpdates
telegram.vendor.ptb_urllib3.urllib3.connectionpool - WARNING - Retrying (Retry(total=0, connect=None, read=None, redirect=None)) after connection broken by 'NewConnectionError('<telegram.vendor.ptb_urllib3.urllib3.contrib.socks.SOCKSHTTPSConnection object at 0x00000000035EF588>: Failed to establish a new connection: [Errno 11001] getaddrinfo failed',)': /bot596268584:AAEbS5S8eJYm3ksbBy3fluXIrgifedC23lg/getUpdates
telegram.ext.updater - ERROR - Error while getting Updates: urllib3 HTTPError SOCKSHTTPSConnectionPool(host='api.telegram.org', port=443): Max retries exceeded with url: /bot596268584:AAEbS5S8eJYm3ksbBy3fluXIrgifedC23lg/getUpdates (Caused by NewConnectionError('<telegram.vendor.ptb_urllib3.urllib3.contrib.socks.SOCKSHTTPSConnection object at 0x00000000035EFE80>: Failed to establish a new connection: [Errno 11001] getaddrinfo failed',))
telegram.vendor.ptb_urllib3.urllib3.connectionpool - WARNING - Retrying (Retry(total=2, connect=None, read=None, redirect=None)) after connection broken by 'NewConnectionError('<telegram.vendor.ptb_urllib3.urllib3.contrib.socks.SOCKSHTTPSConnection object at 0x0000000005156DD8>: Failed to establish a new connection: [Errno 11001] getaddrinfo failed',)': /bot596268584:AAEbS5S8eJYm3ksbBy3fluXIrgifedC23lg/getUpdates
telegram.vendor.ptb_urllib3.urllib3.connectionpool - WARNING - Retrying (Retry(total=1, connect=None, read=None, redirect=None)) after connection broken by 'NewConnectionError('<telegram.vendor.ptb_urllib3.urllib3.contrib.socks.SOCKSHTTPSConnection object at 0x00000000035EFCC0>: Failed to establish a new connection: [Errno 11001] getaddrinfo failed',)': /bot596268584:AAEbS5S8eJYm3ksbBy3fluXIrgifedC23lg/getUpdates
telegram.vendor.ptb_urllib3.urllib3.connectionpool - WARNING - Retrying (Retry(total=0, connect=None, read=None, redirect=None)) after connection broken by 'NewConnectionError('<telegram.vendor.ptb_urllib3.urllib3.contrib.socks.SOCKSHTTPSConnection object at 0x00000000035EFCF8>: Failed to establish a new connection: [Errno 11001] getaddrinfo failed',)': /bot596268584:AAEbS5S8eJYm3ksbBy3fluXIrgifedC23lg/getUpdates
telegram.ext.updater - ERROR - Error while getting Updates: urllib3 HTTPError SOCKSHTTPSConnectionPool(host='api.telegram.org', port=443): Max retries exceeded with url: /bot596268584:AAEbS5S8eJYm3ksbBy3fluXIrgifedC23lg/getUpdates (Caused by NewConnectionError('<telegram.vendor.ptb_urllib3.urllib3.contrib.socks.SOCKSHTTPSConnection object at 0x00000000035EFBA8>: Failed to establish a new connection: [Errno 11001] getaddrinfo failed',))
telegram.vendor.ptb_urllib3.urllib3.connectionpool - WARNING - Retrying (Retry(total=2, connect=None, read=None, redirect=None)) after connection broken by 'NewConnectionError('<telegram.vendor.ptb_urllib3.urllib3.contrib.socks.SOCKSHTTPSConnection object at 0x00000000035EFC50>: Failed to establish a new connection: [Errno 11001] getaddrinfo failed',)': /bot596268584:AAEbS5S8eJYm3ksbBy3fluXIrgifedC23lg/getUpdates
telegram.vendor.ptb_urllib3.urllib3.connectionpool - WARNING - Retrying (Retry(total=1, connect=None, read=None, redirect=None)) after connection broken by 'NewConnectionError('<telegram.vendor.ptb_urllib3.urllib3.contrib.socks.SOCKSHTTPSConnection object at 0x00000000035EF9B0>: Failed to establish a new connection: [Errno 11001] getaddrinfo failed',)': /bot596268584:AAEbS5S8eJYm3ksbBy3fluXIrgifedC23lg/getUpdates
telegram.vendor.ptb_urllib3.urllib3.connectionpool - WARNING - Retrying (Retry(total=0, connect=None, read=None, redirect=None)) after connection broken by 'NewConnectionError('<telegram.vendor.ptb_urllib3.urllib3.contrib.socks.SOCKSHTTPSConnection object at 0x0000000005156FD0>: Failed to establish a new connection: [Errno 11001] getaddrinfo failed',)': /bot596268584:AAEbS5S8eJYm3ksbBy3fluXIrgifedC23lg/getUpdates
telegram.ext.updater - ERROR - Error while getting Updates: urllib3 HTTPError SOCKSHTTPSConnectionPool(host='api.telegram.org', port=443): Max retries exceeded with url: /bot596268584:AAEbS5S8eJYm3ksbBy3fluXIrgifedC23lg/getUpdates (Caused by NewConnectionError('<telegram.vendor.ptb_urllib3.urllib3.contrib.socks.SOCKSHTTPSConnection object at 0x0000000005156F98>: Failed to establish a new connection: [Errno 11001] getaddrinfo failed',))
telegram.vendor.ptb_urllib3.urllib3.connectionpool - WARNING - Retrying (Retry(total=2, connect=None, read=None, redirect=None)) after connection broken by 'NewConnectionError('<telegram.vendor.ptb_urllib3.urllib3.contrib.socks.SOCKSHTTPSConnection object at 0x0000000005156BA8>: Failed to establish a new connection: [Errno 11001] getaddrinfo failed',)': /bot596268584:AAEbS5S8eJYm3ksbBy3fluXIrgifedC23lg/getUpdates
telegram.vendor.ptb_urllib3.urllib3.connectionpool - WARNING - Retrying (Retry(total=1, connect=None, read=None, redirect=None)) after connection broken by 'NewConnectionError('<telegram.vendor.ptb_urllib3.urllib3.contrib.socks.SOCKSHTTPSConnection object at 0x0000000005156748>: Failed to establish a new connection: [Errno 11001] getaddrinfo failed',)': /bot596268584:AAEbS5S8eJYm3ksbBy3fluXIrgifedC23lg/getUpdates
telegram.vendor.ptb_urllib3.urllib3.connectionpool - WARNING - Retrying (Retry(total=0, connect=None, read=None, redirect=None)) after connection broken by 'NewConnectionError('<telegram.vendor.ptb_urllib3.urllib3.contrib.socks.SOCKSHTTPSConnection object at 0x0000000005156DA0>: Failed to establish a new connection: [Errno 11001] getaddrinfo failed',)': /bot596268584:AAEbS5S8eJYm3ksbBy3fluXIrgifedC23lg/getUpdates
telegram.ext.updater - ERROR - Error while getting Updates: urllib3 HTTPError SOCKSHTTPSConnectionPool(host='api.telegram.org', port=443): Max retries exceeded with url: /bot596268584:AAEbS5S8eJYm3ksbBy3fluXIrgifedC23lg/getUpdates (Caused by NewConnectionError('<telegram.vendor.ptb_urllib3.urllib3.contrib.socks.SOCKSHTTPSConnection object at 0x0000000005156F60>: Failed to establish a new connection: [Errno 11001] getaddrinfo failed',))
telegram.vendor.ptb_urllib3.urllib3.connectionpool - WARNING - Retrying (Retry(total=2, connect=None, read=None, redirect=None)) after connection broken by 'NewConnectionError('<telegram.vendor.ptb_urllib3.urllib3.contrib.socks.SOCKSHTTPSConnection object at 0x0000000005156A58>: Failed to establish a new connection: [Errno 11001] getaddrinfo failed',)': /bot596268584:AAEbS5S8eJYm3ksbBy3fluXIrgifedC23lg/getUpdates
telegram.vendor.ptb_urllib3.urllib3.connectionpool - WARNING - Retrying (Retry(total=1, connect=None, read=None, redirect=None)) after connection broken by 'NewConnectionError('<telegram.vendor.ptb_urllib3.urllib3.contrib.socks.SOCKSHTTPSConnection object at 0x0000000005156978>: Failed to establish a new connection: [Errno 11001] getaddrinfo failed',)': /bot596268584:AAEbS5S8eJYm3ksbBy3fluXIrgifedC23lg/getUpdates
telegram.vendor.ptb_urllib3.urllib3.connectionpool - WARNING - Retrying (Retry(total=0, connect=None, read=None, redirect=None)) after connection broken by 'NewConnectionError('<telegram.vendor.ptb_urllib3.urllib3.contrib.socks.SOCKSHTTPSConnection object at 0x0000000005156860>: Failed to establish a new connection: [Errno 11001] getaddrinfo failed',)': /bot596268584:AAEbS5S8eJYm3ksbBy3fluXIrgifedC23lg/getUpdates
telegram.ext.updater - ERROR - Error while getting Updates: urllib3 HTTPError SOCKSHTTPSConnectionPool(host='api.telegram.org', port=443): Max retries exceeded with url: /bot596268584:AAEbS5S8eJYm3ksbBy3fluXIrgifedC23lg/getUpdates (Caused by NewConnectionError('<telegram.vendor.ptb_urllib3.urllib3.contrib.socks.SOCKSHTTPSConnection object at 0x00000000035CCF60>: Failed to establish a new connection: [Errno 11001] getaddrinfo failed',))
telegram.vendor.ptb_urllib3.urllib3.connectionpool - WARNING - Retrying (Retry(total=2, connect=None, read=None, redirect=None)) after connection broken by 'NewConnectionError('<telegram.vendor.ptb_urllib3.urllib3.contrib.socks.SOCKSHTTPSConnection object at 0x00000000051567B8>: Failed to establish a new connection: [Errno 11001] getaddrinfo failed',)': /bot596268584:AAEbS5S8eJYm3ksbBy3fluXIrgifedC23lg/getUpdates
telegram.vendor.ptb_urllib3.urllib3.connectionpool - WARNING - Retrying (Retry(total=1, connect=None, read=None, redirect=None)) after connection broken by 'NewConnectionError('<telegram.vendor.ptb_urllib3.urllib3.contrib.socks.SOCKSHTTPSConnection object at 0x00000000035CC208>: Failed to establish a new connection: [Errno 11001] getaddrinfo failed',)': /bot596268584:AAEbS5S8eJYm3ksbBy3fluXIrgifedC23lg/getUpdates
telegram.vendor.ptb_urllib3.urllib3.connectionpool - WARNING - Retrying (Retry(total=0, connect=None, read=None, redirect=None)) after connection broken by 'NewConnectionError('<telegram.vendor.ptb_urllib3.urllib3.contrib.socks.SOCKSHTTPSConnection object at 0x00000000035CCB70>: Failed to establish a new connection: [Errno 11001] getaddrinfo failed',)': /bot596268584:AAEbS5S8eJYm3ksbBy3fluXIrgifedC23lg/getUpdates
telegram.ext.updater - ERROR - Error while getting Updates: urllib3 HTTPError SOCKSHTTPSConnectionPool(host='api.telegram.org', port=443): Max retries exceeded with url: /bot596268584:AAEbS5S8eJYm3ksbBy3fluXIrgifedC23lg/getUpdates (Caused by NewConnectionError('<telegram.vendor.ptb_urllib3.urllib3.contrib.socks.SOCKSHTTPSConnection object at 0x00000000035EF6A0>: Failed to establish a new connection: [Errno 11001] getaddrinfo failed',))
telegram.vendor.ptb_urllib3.urllib3.connectionpool - WARNING - Retrying (Retry(total=2, connect=None, read=None, redirect=None)) after connection broken by 'NewConnectionError('<telegram.vendor.ptb_urllib3.urllib3.contrib.socks.SOCKSHTTPSConnection object at 0x00000000035CC940>: Failed to establish a new connection: [Errno 11001] getaddrinfo failed',)': /bot596268584:AAEbS5S8eJYm3ksbBy3fluXIrgifedC23lg/getUpdates
telegram.vendor.ptb_urllib3.urllib3.connectionpool - WARNING - Retrying (Retry(total=1, connect=None, read=None, redirect=None)) after connection broken by 'NewConnectionError('<telegram.vendor.ptb_urllib3.urllib3.contrib.socks.SOCKSHTTPSConnection object at 0x00000000035EF630>: Failed to establish a new connection: [Errno 11001] getaddrinfo failed',)': /bot596268584:AAEbS5S8eJYm3ksbBy3fluXIrgifedC23lg/getUpdates
telegram.vendor.ptb_urllib3.urllib3.connectionpool - WARNING - Retrying (Retry(total=0, connect=None, read=None, redirect=None)) after connection broken by 'NewConnectionError('<telegram.vendor.ptb_urllib3.urllib3.contrib.socks.SOCKSHTTPSConnection object at 0x00000000035EF4E0>: Failed to establish a new connection: [Errno 11001] getaddrinfo failed',)': /bot596268584:AAEbS5S8eJYm3ksbBy3fluXIrgifedC23lg/getUpdates
telegram.ext.updater - ERROR - Error while getting Updates: urllib3 HTTPError SOCKSHTTPSConnectionPool(host='api.telegram.org', port=443): Max retries exceeded with url: /bot596268584:AAEbS5S8eJYm3ksbBy3fluXIrgifedC23lg/getUpdates (Caused by NewConnectionError('<telegram.vendor.ptb_urllib3.urllib3.contrib.socks.SOCKSHTTPSConnection object at 0x00000000035EFEF0>: Failed to establish a new connection: [Errno 11001] getaddrinfo failed',))
telegram.vendor.ptb_urllib3.urllib3.connectionpool - WARNING - Retrying (Retry(total=2, connect=None, read=None, redirect=None)) after connection broken by 'NewConnectionError('<telegram.vendor.ptb_urllib3.urllib3.contrib.socks.SOCKSHTTPSConnection object at 0x00000000035EF668>: Failed to establish a new connection: [Errno 11001] getaddrinfo failed',)': /bot596268584:AAEbS5S8eJYm3ksbBy3fluXIrgifedC23lg/getUpdates
telegram.vendor.ptb_urllib3.urllib3.connectionpool - WARNING - Retrying (Retry(total=1, connect=None, read=None, redirect=None)) after connection broken by 'NewConnectionError('<telegram.vendor.ptb_urllib3.urllib3.contrib.socks.SOCKSHTTPSConnection object at 0x00000000035EF048>: Failed to establish a new connection: [Errno 11001] getaddrinfo failed',)': /bot596268584:AAEbS5S8eJYm3ksbBy3fluXIrgifedC23lg/getUpdates
telegram.vendor.ptb_urllib3.urllib3.connectionpool - WARNING - Retrying (Retry(total=0, connect=None, read=None, redirect=None)) after connection broken by 'NewConnectionError('<telegram.vendor.ptb_urllib3.urllib3.contrib.socks.SOCKSHTTPSConnection object at 0x00000000035EF400>: Failed to establish a new connection: [Errno 11001] getaddrinfo failed',)': /bot596268584:AAEbS5S8eJYm3ksbBy3fluXIrgifedC23lg/getUpdates
telegram.ext.updater - ERROR - Error while getting Updates: urllib3 HTTPError SOCKSHTTPSConnectionPool(host='api.telegram.org', port=443): Max retries exceeded with url: /bot596268584:AAEbS5S8eJYm3ksbBy3fluXIrgifedC23lg/getUpdates (Caused by NewConnectionError('<telegram.vendor.ptb_urllib3.urllib3.contrib.socks.SOCKSHTTPSConnection object at 0x00000000035EFBE0>: Failed to establish a new connection: [Errno 11001] getaddrinfo failed',))
telegram.vendor.ptb_urllib3.urllib3.connectionpool - WARNING - Retrying (Retry(total=2, connect=None, read=None, redirect=None)) after connection broken by 'NewConnectionError('<telegram.vendor.ptb_urllib3.urllib3.contrib.socks.SOCKSHTTPSConnection object at 0x00000000035EF438>: Failed to establish a new connection: [Errno 11001] getaddrinfo failed',)': /bot596268584:AAEbS5S8eJYm3ksbBy3fluXIrgifedC23lg/getUpdates
telegram.vendor.ptb_urllib3.urllib3.connectionpool - WARNING - Retrying (Retry(total=1, connect=None, read=None, redirect=None)) after connection broken by 'NewConnectionError('<telegram.vendor.ptb_urllib3.urllib3.contrib.socks.SOCKSHTTPSConnection object at 0x00000000035EFAC8>: Failed to establish a new connection: [Errno 11001] getaddrinfo failed',)': /bot596268584:AAEbS5S8eJYm3ksbBy3fluXIrgifedC23lg/getUpdates
telegram.vendor.ptb_urllib3.urllib3.connectionpool - WARNING - Retrying (Retry(total=0, connect=None, read=None, redirect=None)) after connection broken by 'NewConnectionError('<telegram.vendor.ptb_urllib3.urllib3.contrib.socks.SOCKSHTTPSConnection object at 0x00000000035EF358>: Failed to establish a new connection: [Errno 11001] getaddrinfo failed',)': /bot596268584:AAEbS5S8eJYm3ksbBy3fluXIrgifedC23lg/getUpdates
telegram.ext.updater - ERROR - Error while getting Updates: urllib3 HTTPError SOCKSHTTPSConnectionPool(host='api.telegram.org', port=443): Max retries exceeded with url: /bot596268584:AAEbS5S8eJYm3ksbBy3fluXIrgifedC23lg/getUpdates (Caused by NewConnectionError('<telegram.vendor.ptb_urllib3.urllib3.contrib.socks.SOCKSHTTPSConnection object at 0x00000000035EFE10>: Failed to establish a new connection: [Errno 11001] getaddrinfo failed',))
telegram.vendor.ptb_urllib3.urllib3.connectionpool - WARNING - Retrying (Retry(total=2, connect=None, read=None, redirect=None)) after connection broken by 'NewConnectionError('<telegram.vendor.ptb_urllib3.urllib3.contrib.socks.SOCKSHTTPSConnection object at 0x00000000035EF470>: Failed to establish a new connection: [Errno 11001] getaddrinfo failed',)': /bot596268584:AAEbS5S8eJYm3ksbBy3fluXIrgifedC23lg/getUpdates
telegram.vendor.ptb_urllib3.urllib3.connectionpool - WARNING - Retrying (Retry(total=1, connect=None, read=None, redirect=None)) after connection broken by 'NewConnectionError('<telegram.vendor.ptb_urllib3.urllib3.contrib.socks.SOCKSHTTPSConnection object at 0x0000000005156F60>: Failed to establish a new connection: [Errno 11001] getaddrinfo failed',)': /bot596268584:AAEbS5S8eJYm3ksbBy3fluXIrgifedC23lg/getUpdates
telegram.vendor.ptb_urllib3.urllib3.connectionpool - WARNING - Retrying (Retry(total=0, connect=None, read=None, redirect=None)) after connection broken by 'NewConnectionError('<telegram.vendor.ptb_urllib3.urllib3.contrib.socks.SOCKSHTTPSConnection object at 0x00000000051567F0>: Failed to establish a new connection: [Errno 11001] getaddrinfo failed',)': /bot596268584:AAEbS5S8eJYm3ksbBy3fluXIrgifedC23lg/getUpdates
telegram.ext.updater - ERROR - Error while getting Updates: urllib3 HTTPError SOCKSHTTPSConnectionPool(host='api.telegram.org', port=443): Max retries exceeded with url: /bot596268584:AAEbS5S8eJYm3ksbBy3fluXIrgifedC23lg/getUpdates (Caused by NewConnectionError('<telegram.vendor.ptb_urllib3.urllib3.contrib.socks.SOCKSHTTPSConnection object at 0x0000000005156F98>: Failed to establish a new connection: [Errno 11001] getaddrinfo failed',))
telegram.vendor.ptb_urllib3.urllib3.connectionpool - WARNING - Retrying (Retry(total=2, connect=None, read=None, redirect=None)) after connection broken by 'NewConnectionError('<telegram.vendor.ptb_urllib3.urllib3.contrib.socks.SOCKSHTTPSConnection object at 0x0000000005156908>: Failed to establish a new connection: [Errno 11001] getaddrinfo failed',)': /bot596268584:AAEbS5S8eJYm3ksbBy3fluXIrgifedC23lg/getUpdates
telegram.vendor.ptb_urllib3.urllib3.connectionpool - WARNING - Retrying (Retry(total=1, connect=None, read=None, redirect=None)) after connection broken by 'NewConnectionError('<telegram.vendor.ptb_urllib3.urllib3.contrib.socks.SOCKSHTTPSConnection object at 0x0000000005156C18>: Failed to establish a new connection: [Errno 11001] getaddrinfo failed',)': /bot596268584:AAEbS5S8eJYm3ksbBy3fluXIrgifedC23lg/getUpdates
telegram.vendor.ptb_urllib3.urllib3.connectionpool - WARNING - Retrying (Retry(total=0, connect=None, read=None, redirect=None)) after connection broken by 'NewConnectionError('<telegram.vendor.ptb_urllib3.urllib3.contrib.socks.SOCKSHTTPSConnection object at 0x0000000005156160>: Failed to establish a new connection: [Errno 11001] getaddrinfo failed',)': /bot596268584:AAEbS5S8eJYm3ksbBy3fluXIrgifedC23lg/getUpdates
telegram.ext.updater - ERROR - Error while getting Updates: urllib3 HTTPError SOCKSHTTPSConnectionPool(host='api.telegram.org', port=443): Max retries exceeded with url: /bot596268584:AAEbS5S8eJYm3ksbBy3fluXIrgifedC23lg/getUpdates (Caused by NewConnectionError('<telegram.vendor.ptb_urllib3.urllib3.contrib.socks.SOCKSHTTPSConnection object at 0x0000000005156780>: Failed to establish a new connection: [Errno 11001] getaddrinfo failed',))
telegram.vendor.ptb_urllib3.urllib3.connectionpool - WARNING - Retrying (Retry(total=2, connect=None, read=None, redirect=None)) after connection broken by 'NewConnectionError('<telegram.vendor.ptb_urllib3.urllib3.contrib.socks.SOCKSHTTPSConnection object at 0x0000000005156F28>: Failed to establish a new connection: [Errno 11001] getaddrinfo failed',)': /bot596268584:AAEbS5S8eJYm3ksbBy3fluXIrgifedC23lg/getUpdates
telegram.vendor.ptb_urllib3.urllib3.connectionpool - WARNING - Retrying (Retry(total=1, connect=None, read=None, redirect=None)) after connection broken by 'NewConnectionError('<telegram.vendor.ptb_urllib3.urllib3.contrib.socks.SOCKSHTTPSConnection object at 0x0000000005156240>: Failed to establish a new connection: [Errno 11001] getaddrinfo failed',)': /bot596268584:AAEbS5S8eJYm3ksbBy3fluXIrgifedC23lg/getUpdates
telegram.vendor.ptb_urllib3.urllib3.connectionpool - WARNING - Retrying (Retry(total=0, connect=None, read=None, redirect=None)) after connection broken by 'NewConnectionError('<telegram.vendor.ptb_urllib3.urllib3.contrib.socks.SOCKSHTTPSConnection object at 0x00000000051562E8>: Failed to establish a new connection: [Errno 11001] getaddrinfo failed',)': /bot596268584:AAEbS5S8eJYm3ksbBy3fluXIrgifedC23lg/getUpdates
telegram.ext.updater - ERROR - Error while getting Updates: urllib3 HTTPError SOCKSHTTPSConnectionPool(host='api.telegram.org', port=443): Max retries exceeded with url: /bot596268584:AAEbS5S8eJYm3ksbBy3fluXIrgifedC23lg/getUpdates (Caused by NewConnectionError('<telegram.vendor.ptb_urllib3.urllib3.contrib.socks.SOCKSHTTPSConnection object at 0x00000000051562B0>: Failed to establish a new connection: [Errno 11001] getaddrinfo failed',))
telegram.vendor.ptb_urllib3.urllib3.connectionpool - WARNING - Retrying (Retry(total=2, connect=None, read=None, redirect=None)) after connection broken by 'NewConnectionError('<telegram.vendor.ptb_urllib3.urllib3.contrib.socks.SOCKSHTTPSConnection object at 0x00000000051569B0>: Failed to establish a new connection: [Errno 11001] getaddrinfo failed',)': /bot596268584:AAEbS5S8eJYm3ksbBy3fluXIrgifedC23lg/getUpdates
telegram.vendor.ptb_urllib3.urllib3.connectionpool - WARNING - Retrying (Retry(total=1, connect=None, read=None, redirect=None)) after connection broken by 'NewConnectionError('<telegram.vendor.ptb_urllib3.urllib3.contrib.socks.SOCKSHTTPSConnection object at 0x0000000005156FD0>: Failed to establish a new connection: [Errno 11001] getaddrinfo failed',)': /bot596268584:AAEbS5S8eJYm3ksbBy3fluXIrgifedC23lg/getUpdates
telegram.vendor.ptb_urllib3.urllib3.connectionpool - WARNING - Retrying (Retry(total=0, connect=None, read=None, redirect=None)) after connection broken by 'NewConnectionError('<telegram.vendor.ptb_urllib3.urllib3.contrib.socks.SOCKSHTTPSConnection object at 0x0000000005162358>: Failed to establish a new connection: [Errno 11001] getaddrinfo failed',)': /bot596268584:AAEbS5S8eJYm3ksbBy3fluXIrgifedC23lg/getUpdates
telegram.ext.updater - ERROR - Error while getting Updates: urllib3 HTTPError SOCKSHTTPSConnectionPool(host='api.telegram.org', port=443): Max retries exceeded with url: /bot596268584:AAEbS5S8eJYm3ksbBy3fluXIrgifedC23lg/getUpdates (Caused by NewConnectionError('<telegram.vendor.ptb_urllib3.urllib3.contrib.socks.SOCKSHTTPSConnection object at 0x0000000005162550>: Failed to establish a new connection: [Errno 11001] getaddrinfo failed',))
telegram.vendor.ptb_urllib3.urllib3.connectionpool - WARNING - Retrying (Retry(total=2, connect=None, read=None, redirect=None)) after connection broken by 'NewConnectionError('<telegram.vendor.ptb_urllib3.urllib3.contrib.socks.SOCKSHTTPSConnection object at 0x0000000005156390>: Failed to establish a new connection: [Errno 11001] getaddrinfo failed',)': /bot596268584:AAEbS5S8eJYm3ksbBy3fluXIrgifedC23lg/getUpdates
telegram.vendor.ptb_urllib3.urllib3.connectionpool - WARNING - Retrying (Retry(total=1, connect=None, read=None, redirect=None)) after connection broken by 'NewConnectionError('<telegram.vendor.ptb_urllib3.urllib3.contrib.socks.SOCKSHTTPSConnection object at 0x00000000051628D0>: Failed to establish a new connection: [Errno 11001] getaddrinfo failed',)': /bot596268584:AAEbS5S8eJYm3ksbBy3fluXIrgifedC23lg/getUpdates
telegram.vendor.ptb_urllib3.urllib3.connectionpool - WARNING - Retrying (Retry(total=0, connect=None, read=None, redirect=None)) after connection broken by 'NewConnectionError('<telegram.vendor.ptb_urllib3.urllib3.contrib.socks.SOCKSHTTPSConnection object at 0x0000000005162898>: Failed to establish a new connection: [Errno 11001] getaddrinfo failed',)': /bot596268584:AAEbS5S8eJYm3ksbBy3fluXIrgifedC23lg/getUpdates
telegram.ext.updater - ERROR - Error while getting Updates: urllib3 HTTPError SOCKSHTTPSConnectionPool(host='api.telegram.org', port=443): Max retries exceeded with url: /bot596268584:AAEbS5S8eJYm3ksbBy3fluXIrgifedC23lg/getUpdates (Caused by NewConnectionError('<telegram.vendor.ptb_urllib3.urllib3.contrib.socks.SOCKSHTTPSConnection object at 0x00000000051620F0>: Failed to establish a new connection: [Errno 11001] getaddrinfo failed',))
telegram.vendor.ptb_urllib3.urllib3.connectionpool - WARNING - Retrying (Retry(total=2, connect=None, read=None, redirect=None)) after connection broken by 'NewConnectionError('<telegram.vendor.ptb_urllib3.urllib3.contrib.socks.SOCKSHTTPSConnection object at 0x0000000005156C18>: Failed to establish a new connection: [Errno 11001] getaddrinfo failed',)': /bot596268584:AAEbS5S8eJYm3ksbBy3fluXIrgifedC23lg/getUpdates
telegram.vendor.ptb_urllib3.urllib3.connectionpool - WARNING - Retrying (Retry(total=1, connect=None, read=None, redirect=None)) after connection broken by 'NewConnectionError('<telegram.vendor.ptb_urllib3.urllib3.contrib.socks.SOCKSHTTPSConnection object at 0x0000000005156908>: Failed to establish a new connection: [Errno 11001] getaddrinfo failed',)': /bot596268584:AAEbS5S8eJYm3ksbBy3fluXIrgifedC23lg/getUpdates
telegram.vendor.ptb_urllib3.urllib3.connectionpool - WARNING - Retrying (Retry(total=0, connect=None, read=None, redirect=None)) after connection broken by 'NewConnectionError('<telegram.vendor.ptb_urllib3.urllib3.contrib.socks.SOCKSHTTPSConnection object at 0x00000000051567F0>: Failed to establish a new connection: [Errno 11001] getaddrinfo failed',)': /bot596268584:AAEbS5S8eJYm3ksbBy3fluXIrgifedC23lg/getUpdates
telegram.ext.updater - ERROR - Error while getting Updates: urllib3 HTTPError SOCKSHTTPSConnectionPool(host='api.telegram.org', port=443): Max retries exceeded with url: /bot596268584:AAEbS5S8eJYm3ksbBy3fluXIrgifedC23lg/getUpdates (Caused by NewConnectionError('<telegram.vendor.ptb_urllib3.urllib3.contrib.socks.SOCKSHTTPSConnection object at 0x0000000005156208>: Failed to establish a new connection: [Errno 11001] getaddrinfo failed',))
telegram.vendor.ptb_urllib3.urllib3.connectionpool - WARNING - Retrying (Retry(total=2, connect=None, read=None, redirect=None)) after connection broken by 'NewConnectionError('<telegram.vendor.ptb_urllib3.urllib3.contrib.socks.SOCKSHTTPSConnection object at 0x00000000035CCF98>: Failed to establish a new connection: [Errno 11001] getaddrinfo failed',)': /bot596268584:AAEbS5S8eJYm3ksbBy3fluXIrgifedC23lg/getUpdates
telegram.vendor.ptb_urllib3.urllib3.connectionpool - WARNING - Retrying (Retry(total=1, connect=None, read=None, redirect=None)) after connection broken by 'NewConnectionError('<telegram.vendor.ptb_urllib3.urllib3.contrib.socks.SOCKSHTTPSConnection object at 0x00000000035CCD68>: Failed to establish a new connection: [Errno 11001] getaddrinfo failed',)': /bot596268584:AAEbS5S8eJYm3ksbBy3fluXIrgifedC23lg/getUpdates
telegram.vendor.ptb_urllib3.urllib3.connectionpool - WARNING - Retrying (Retry(total=0, connect=None, read=None, redirect=None)) after connection broken by 'NewConnectionError('<telegram.vendor.ptb_urllib3.urllib3.contrib.socks.SOCKSHTTPSConnection object at 0x00000000035CCF60>: Failed to establish a new connection: [Errno 11001] getaddrinfo failed',)': /bot596268584:AAEbS5S8eJYm3ksbBy3fluXIrgifedC23lg/getUpdates
telegram.ext.updater - ERROR - Error while getting Updates: urllib3 HTTPError SOCKSHTTPSConnectionPool(host='api.telegram.org', port=443): Max retries exceeded with url: /bot596268584:AAEbS5S8eJYm3ksbBy3fluXIrgifedC23lg/getUpdates (Caused by NewConnectionError('<telegram.vendor.ptb_urllib3.urllib3.contrib.socks.SOCKSHTTPSConnection object at 0x00000000035CCB00>: Failed to establish a new connection: [Errno 11001] getaddrinfo failed',))
telegram.vendor.ptb_urllib3.urllib3.connectionpool - WARNING - Retrying (Retry(total=2, connect=None, read=None, redirect=None)) after connection broken by 'NewConnectionError('<telegram.vendor.ptb_urllib3.urllib3.contrib.socks.SOCKSHTTPSConnection object at 0x00000000035CCC18>: Failed to establish a new connection: [Errno 11001] getaddrinfo failed',)': /bot596268584:AAEbS5S8eJYm3ksbBy3fluXIrgifedC23lg/getUpdates
telegram.vendor.ptb_urllib3.urllib3.connectionpool - WARNING - Retrying (Retry(total=1, connect=None, read=None, redirect=None)) after connection broken by 'NewConnectionError('<telegram.vendor.ptb_urllib3.urllib3.contrib.socks.SOCKSHTTPSConnection object at 0x00000000035EFF28>: Failed to establish a new connection: [Errno 11001] getaddrinfo failed',)': /bot596268584:AAEbS5S8eJYm3ksbBy3fluXIrgifedC23lg/getUpdates
telegram.vendor.ptb_urllib3.urllib3.connectionpool - WARNING - Retrying (Retry(total=0, connect=None, read=None, redirect=None)) after connection broken by 'NewConnectionError('<telegram.vendor.ptb_urllib3.urllib3.contrib.socks.SOCKSHTTPSConnection object at 0x00000000035EF978>: Failed to establish a new connection: [Errno 11001] getaddrinfo failed',)': /bot596268584:AAEbS5S8eJYm3ksbBy3fluXIrgifedC23lg/getUpdates
telegram.ext.updater - ERROR - Error while getting Updates: urllib3 HTTPError SOCKSHTTPSConnectionPool(host='api.telegram.org', port=443): Max retries exceeded with url: /bot596268584:AAEbS5S8eJYm3ksbBy3fluXIrgifedC23lg/getUpdates (Caused by NewConnectionError('<telegram.vendor.ptb_urllib3.urllib3.contrib.socks.SOCKSHTTPSConnection object at 0x00000000035EF630>: Failed to establish a new connection: [Errno 11001] getaddrinfo failed',))
telegram.vendor.ptb_urllib3.urllib3.connectionpool - WARNING - Retrying (Retry(total=2, connect=None, read=None, redirect=None)) after connection broken by 'NewConnectionError('<telegram.vendor.ptb_urllib3.urllib3.contrib.socks.SOCKSHTTPSConnection object at 0x00000000035EFBE0>: Failed to establish a new connection: [Errno 11001] getaddrinfo failed',)': /bot596268584:AAEbS5S8eJYm3ksbBy3fluXIrgifedC23lg/getUpdates
telegram.vendor.ptb_urllib3.urllib3.connectionpool - WARNING - Retrying (Retry(total=1, connect=None, read=None, redirect=None)) after connection broken by 'NewConnectionError('<telegram.vendor.ptb_urllib3.urllib3.contrib.socks.SOCKSHTTPSConnection object at 0x0000000005162B38>: Failed to establish a new connection: [Errno 11001] getaddrinfo failed',)': /bot596268584:AAEbS5S8eJYm3ksbBy3fluXIrgifedC23lg/getUpdates
telegram.vendor.ptb_urllib3.urllib3.connectionpool - WARNING - Retrying (Retry(total=0, connect=None, read=None, redirect=None)) after connection broken by 'NewConnectionError('<telegram.vendor.ptb_urllib3.urllib3.contrib.socks.SOCKSHTTPSConnection object at 0x0000000005162CF8>: Failed to establish a new connection: [Errno 11001] getaddrinfo failed',)': /bot596268584:AAEbS5S8eJYm3ksbBy3fluXIrgifedC23lg/getUpdates
telegram.ext.updater - ERROR - Error while getting Updates: urllib3 HTTPError SOCKSHTTPSConnectionPool(host='api.telegram.org', port=443): Max retries exceeded with url: /bot596268584:AAEbS5S8eJYm3ksbBy3fluXIrgifedC23lg/getUpdates (Caused by NewConnectionError('<telegram.vendor.ptb_urllib3.urllib3.contrib.socks.SOCKSHTTPSConnection object at 0x0000000005162F98>: Failed to establish a new connection: [Errno 11001] getaddrinfo failed',))
telegram.vendor.ptb_urllib3.urllib3.connectionpool - WARNING - Retrying (Retry(total=2, connect=None, read=None, redirect=None)) after connection broken by 'NewConnectionError('<telegram.vendor.ptb_urllib3.urllib3.contrib.socks.SOCKSHTTPSConnection object at 0x0000000005162A20>: Failed to establish a new connection: [Errno 11001] getaddrinfo failed',)': /bot596268584:AAEbS5S8eJYm3ksbBy3fluXIrgifedC23lg/getUpdates
telegram.vendor.ptb_urllib3.urllib3.connectionpool - WARNING - Retrying (Retry(total=1, connect=None, read=None, redirect=None)) after connection broken by 'NewConnectionError('<telegram.vendor.ptb_urllib3.urllib3.contrib.socks.SOCKSHTTPSConnection object at 0x0000000006198208>: Failed to establish a new connection: [Errno 11001] getaddrinfo failed',)': /bot596268584:AAEbS5S8eJYm3ksbBy3fluXIrgifedC23lg/getUpdates
telegram.vendor.ptb_urllib3.urllib3.connectionpool - WARNING - Retrying (Retry(total=0, connect=None, read=None, redirect=None)) after connection broken by 'NewConnectionError('<telegram.vendor.ptb_urllib3.urllib3.contrib.socks.SOCKSHTTPSConnection object at 0x0000000006198320>: Failed to establish a new connection: [Errno 11001] getaddrinfo failed',)': /bot596268584:AAEbS5S8eJYm3ksbBy3fluXIrgifedC23lg/getUpdates
telegram.ext.updater - ERROR - Error while getting Updates: urllib3 HTTPError SOCKSHTTPSConnectionPool(host='api.telegram.org', port=443): Max retries exceeded with url: /bot596268584:AAEbS5S8eJYm3ksbBy3fluXIrgifedC23lg/getUpdates (Caused by NewConnectionError('<telegram.vendor.ptb_urllib3.urllib3.contrib.socks.SOCKSHTTPSConnection object at 0x0000000006198400>: Failed to establish a new connection: [Errno 11001] getaddrinfo failed',))
telegram.vendor.ptb_urllib3.urllib3.connectionpool - WARNING - Retrying (Retry(total=2, connect=None, read=None, redirect=None)) after connection broken by 'NewConnectionError('<telegram.vendor.ptb_urllib3.urllib3.contrib.socks.SOCKSHTTPSConnection object at 0x00000000061980F0>: Failed to establish a new connection: [Errno 11001] getaddrinfo failed',)': /bot596268584:AAEbS5S8eJYm3ksbBy3fluXIrgifedC23lg/getUpdates
telegram.vendor.ptb_urllib3.urllib3.connectionpool - WARNING - Retrying (Retry(total=1, connect=None, read=None, redirect=None)) after connection broken by 'NewConnectionError('<telegram.vendor.ptb_urllib3.urllib3.contrib.socks.SOCKSHTTPSConnection object at 0x0000000006198668>: Failed to establish a new connection: [Errno 11001] getaddrinfo failed',)': /bot596268584:AAEbS5S8eJYm3ksbBy3fluXIrgifedC23lg/getUpdates
telegram.vendor.ptb_urllib3.urllib3.connectionpool - WARNING - Retrying (Retry(total=0, connect=None, read=None, redirect=None)) after connection broken by 'NewConnectionError('<telegram.vendor.ptb_urllib3.urllib3.contrib.socks.SOCKSHTTPSConnection object at 0x0000000005162DD8>: Failed to establish a new connection: [Errno 11001] getaddrinfo failed',)': /bot596268584:AAEbS5S8eJYm3ksbBy3fluXIrgifedC23lg/getUpdates
telegram.ext.updater - ERROR - Error while getting Updates: urllib3 HTTPError SOCKSHTTPSConnectionPool(host='api.telegram.org', port=443): Max retries exceeded with url: /bot596268584:AAEbS5S8eJYm3ksbBy3fluXIrgifedC23lg/getUpdates (Caused by NewConnectionError('<telegram.vendor.ptb_urllib3.urllib3.contrib.socks.SOCKSHTTPSConnection object at 0x0000000005162978>: Failed to establish a new connection: [Errno 11001] getaddrinfo failed',))
telegram.vendor.ptb_urllib3.urllib3.connectionpool - WARNING - Retrying (Retry(total=2, connect=None, read=None, redirect=None)) after connection broken by 'NewConnectionError('<telegram.vendor.ptb_urllib3.urllib3.contrib.socks.SOCKSHTTPSConnection object at 0x00000000035CCD68>: Failed to establish a new connection: [Errno 11001] getaddrinfo failed',)': /bot596268584:AAEbS5S8eJYm3ksbBy3fluXIrgifedC23lg/getUpdates
telegram.vendor.ptb_urllib3.urllib3.connectionpool - WARNING - Retrying (Retry(total=1, connect=None, read=None, redirect=None)) after connection broken by 'NewConnectionError('<telegram.vendor.ptb_urllib3.urllib3.contrib.socks.SOCKSHTTPSConnection object at 0x00000000035CCF98>: Failed to establish a new connection: [Errno 11001] getaddrinfo failed',)': /bot596268584:AAEbS5S8eJYm3ksbBy3fluXIrgifedC23lg/getUpdates
telegram.vendor.ptb_urllib3.urllib3.connectionpool - WARNING - Retrying (Retry(total=0, connect=None, read=None, redirect=None)) after connection broken by 'NewConnectionError('<telegram.vendor.ptb_urllib3.urllib3.contrib.socks.SOCKSHTTPSConnection object at 0x0000000002788860>: Failed to establish a new connection: [Errno 11001] getaddrinfo failed',)': /bot596268584:AAEbS5S8eJYm3ksbBy3fluXIrgifedC23lg/getUpdates
telegram.ext.updater - ERROR - Error while getting Updates: urllib3 HTTPError SOCKSHTTPSConnectionPool(host='api.telegram.org', port=443): Max retries exceeded with url: /bot596268584:AAEbS5S8eJYm3ksbBy3fluXIrgifedC23lg/getUpdates (Caused by NewConnectionError('<telegram.vendor.ptb_urllib3.urllib3.contrib.socks.SOCKSHTTPSConnection object at 0x0000000005156208>: Failed to establish a new connection: [Errno 11001] getaddrinfo failed',))
telegram.vendor.ptb_urllib3.urllib3.connectionpool - WARNING - Retrying (Retry(total=2, connect=None, read=None, redirect=None)) after connection broken by 'NewConnectionError('<telegram.vendor.ptb_urllib3.urllib3.contrib.socks.SOCKSHTTPSConnection object at 0x00000000035CC940>: Failed to establish a new connection: [Errno 11001] getaddrinfo failed',)': /bot596268584:AAEbS5S8eJYm3ksbBy3fluXIrgifedC23lg/getUpdates
telegram.vendor.ptb_urllib3.urllib3.connectionpool - WARNING - Retrying (Retry(total=1, connect=None, read=None, redirect=None)) after connection broken by 'NewConnectionError('<telegram.vendor.ptb_urllib3.urllib3.contrib.socks.SOCKSHTTPSConnection object at 0x0000000005156978>: Failed to establish a new connection: [Errno 11001] getaddrinfo failed',)': /bot596268584:AAEbS5S8eJYm3ksbBy3fluXIrgifedC23lg/getUpdates
telegram.vendor.ptb_urllib3.urllib3.connectionpool - WARNING - Retrying (Retry(total=0, connect=None, read=None, redirect=None)) after connection broken by 'NewConnectionError('<telegram.vendor.ptb_urllib3.urllib3.contrib.socks.SOCKSHTTPSConnection object at 0x0000000005156BE0>: Failed to establish a new connection: [Errno 11001] getaddrinfo failed',)': /bot596268584:AAEbS5S8eJYm3ksbBy3fluXIrgifedC23lg/getUpdates
telegram.ext.updater - ERROR - Error while getting Updates: urllib3 HTTPError SOCKSHTTPSConnectionPool(host='api.telegram.org', port=443): Max retries exceeded with url: /bot596268584:AAEbS5S8eJYm3ksbBy3fluXIrgifedC23lg/getUpdates (Caused by NewConnectionError('<telegram.vendor.ptb_urllib3.urllib3.contrib.socks.SOCKSHTTPSConnection object at 0x0000000005156A20>: Failed to establish a new connection: [Errno 11001] getaddrinfo failed',))
telegram.vendor.ptb_urllib3.urllib3.connectionpool - WARNING - Retrying (Retry(total=2, connect=None, read=None, redirect=None)) after connection broken by 'NewConnectionError('<telegram.vendor.ptb_urllib3.urllib3.contrib.socks.SOCKSHTTPSConnection object at 0x0000000005156F60>: Failed to establish a new connection: [Errno 11001] getaddrinfo failed',)': /bot596268584:AAEbS5S8eJYm3ksbBy3fluXIrgifedC23lg/getUpdates
telegram.vendor.ptb_urllib3.urllib3.connectionpool - WARNING - Retrying (Retry(total=1, connect=None, read=None, redirect=None)) after connection broken by 'NewConnectionError('<telegram.vendor.ptb_urllib3.urllib3.contrib.socks.SOCKSHTTPSConnection object at 0x0000000005156630>: Failed to establish a new connection: [Errno 11001] getaddrinfo failed',)': /bot596268584:AAEbS5S8eJYm3ksbBy3fluXIrgifedC23lg/getUpdates
telegram.vendor.ptb_urllib3.urllib3.connectionpool - WARNING - Retrying (Retry(total=0, connect=None, read=None, redirect=None)) after connection broken by 'NewConnectionError('<telegram.vendor.ptb_urllib3.urllib3.contrib.socks.SOCKSHTTPSConnection object at 0x0000000005156B00>: Failed to establish a new connection: [Errno 11001] getaddrinfo failed',)': /bot596268584:AAEbS5S8eJYm3ksbBy3fluXIrgifedC23lg/getUpdates
telegram.ext.updater - ERROR - Error while getting Updates: urllib3 HTTPError SOCKSHTTPSConnectionPool(host='api.telegram.org', port=443): Max retries exceeded with url: /bot596268584:AAEbS5S8eJYm3ksbBy3fluXIrgifedC23lg/getUpdates (Caused by NewConnectionError('<telegram.vendor.ptb_urllib3.urllib3.contrib.socks.SOCKSHTTPSConnection object at 0x0000000005156EF0>: Failed to establish a new connection: [Errno 11001] getaddrinfo failed',))
telegram.vendor.ptb_urllib3.urllib3.connectionpool - WARNING - Retrying (Retry(total=2, connect=None, read=None, redirect=None)) after connection broken by 'NewConnectionError('<telegram.vendor.ptb_urllib3.urllib3.contrib.socks.SOCKSHTTPSConnection object at 0x0000000005156EB8>: Failed to establish a new connection: [Errno 11001] getaddrinfo failed',)': /bot596268584:AAEbS5S8eJYm3ksbBy3fluXIrgifedC23lg/getUpdates
telegram.vendor.ptb_urllib3.urllib3.connectionpool - WARNING - Retrying (Retry(total=1, connect=None, read=None, redirect=None)) after connection broken by 'NewConnectionError('<telegram.vendor.ptb_urllib3.urllib3.contrib.socks.SOCKSHTTPSConnection object at 0x00000000061984A8>: Failed to establish a new connection: [Errno 11001] getaddrinfo failed',)': /bot596268584:AAEbS5S8eJYm3ksbBy3fluXIrgifedC23lg/getUpdates
telegram.vendor.ptb_urllib3.urllib3.connectionpool - WARNING - Retrying (Retry(total=0, connect=None, read=None, redirect=None)) after connection broken by 'NewConnectionError('<telegram.vendor.ptb_urllib3.urllib3.contrib.socks.SOCKSHTTPSConnection object at 0x0000000006198748>: Failed to establish a new connection: [Errno 11001] getaddrinfo failed',)': /bot596268584:AAEbS5S8eJYm3ksbBy3fluXIrgifedC23lg/getUpdates
telegram.ext.updater - ERROR - Error while getting Updates: urllib3 HTTPError SOCKSHTTPSConnectionPool(host='api.telegram.org', port=443): Max retries exceeded with url: /bot596268584:AAEbS5S8eJYm3ksbBy3fluXIrgifedC23lg/getUpdates (Caused by NewConnectionError('<telegram.vendor.ptb_urllib3.urllib3.contrib.socks.SOCKSHTTPSConnection object at 0x0000000006198860>: Failed to establish a new connection: [Errno 11001] getaddrinfo failed',))
telegram.vendor.ptb_urllib3.urllib3.connectionpool - WARNING - Retrying (Retry(total=2, connect=None, read=None, redirect=None)) after connection broken by 'NewConnectionError('<telegram.vendor.ptb_urllib3.urllib3.contrib.socks.SOCKSHTTPSConnection object at 0x0000000005156A58>: Failed to establish a new connection: [Errno 11001] getaddrinfo failed',)': /bot596268584:AAEbS5S8eJYm3ksbBy3fluXIrgifedC23lg/getUpdates
telegram.vendor.ptb_urllib3.urllib3.connectionpool - WARNING - Retrying (Retry(total=1, connect=None, read=None, redirect=None)) after connection broken by 'NewConnectionError('<telegram.vendor.ptb_urllib3.urllib3.contrib.socks.SOCKSHTTPSConnection object at 0x0000000006198AC8>: Failed to establish a new connection: [Errno 11001] getaddrinfo failed',)': /bot596268584:AAEbS5S8eJYm3ksbBy3fluXIrgifedC23lg/getUpdates
telegram.vendor.ptb_urllib3.urllib3.connectionpool - WARNING - Retrying (Retry(total=0, connect=None, read=None, redirect=None)) after connection broken by 'NewConnectionError('<telegram.vendor.ptb_urllib3.urllib3.contrib.socks.SOCKSHTTPSConnection object at 0x0000000006198BE0>: Failed to establish a new connection: [Errno 11001] getaddrinfo failed',)': /bot596268584:AAEbS5S8eJYm3ksbBy3fluXIrgifedC23lg/getUpdates
telegram.ext.updater - ERROR - Error while getting Updates: urllib3 HTTPError SOCKSHTTPSConnectionPool(host='api.telegram.org', port=443): Max retries exceeded with url: /bot596268584:AAEbS5S8eJYm3ksbBy3fluXIrgifedC23lg/getUpdates (Caused by NewConnectionError('<telegram.vendor.ptb_urllib3.urllib3.contrib.socks.SOCKSHTTPSConnection object at 0x0000000006198CC0>: Failed to establish a new connection: [Errno 11001] getaddrinfo failed',))
telegram.vendor.ptb_urllib3.urllib3.connectionpool - WARNING - Retrying (Retry(total=2, connect=None, read=None, redirect=None)) after connection broken by 'NewConnectionError('<telegram.vendor.ptb_urllib3.urllib3.contrib.socks.SOCKSHTTPSConnection object at 0x00000000061989B0>: Failed to establish a new connection: [Errno 11001] getaddrinfo failed',)': /bot596268584:AAEbS5S8eJYm3ksbBy3fluXIrgifedC23lg/getUpdates
telegram.vendor.ptb_urllib3.urllib3.connectionpool - WARNING - Retrying (Retry(total=1, connect=None, read=None, redirect=None)) after connection broken by 'NewConnectionError('<telegram.vendor.ptb_urllib3.urllib3.contrib.socks.SOCKSHTTPSConnection object at 0x0000000006198F28>: Failed to establish a new connection: [Errno 11001] getaddrinfo failed',)': /bot596268584:AAEbS5S8eJYm3ksbBy3fluXIrgifedC23lg/getUpdates
telegram.vendor.ptb_urllib3.urllib3.connectionpool - WARNING - Retrying (Retry(total=0, connect=None, read=None, redirect=None)) after connection broken by 'NewConnectionError('<telegram.vendor.ptb_urllib3.urllib3.contrib.socks.SOCKSHTTPSConnection object at 0x0000000005156EB8>: Failed to establish a new connection: [Errno 11001] getaddrinfo failed',)': /bot596268584:AAEbS5S8eJYm3ksbBy3fluXIrgifedC23lg/getUpdates
telegram.ext.updater - ERROR - Error while getting Updates: urllib3 HTTPError SOCKSHTTPSConnectionPool(host='api.telegram.org', port=443): Max retries exceeded with url: /bot596268584:AAEbS5S8eJYm3ksbBy3fluXIrgifedC23lg/getUpdates (Caused by NewConnectionError('<telegram.vendor.ptb_urllib3.urllib3.contrib.socks.SOCKSHTTPSConnection object at 0x00000000051562E8>: Failed to establish a new connection: [Errno 11001] getaddrinfo failed',))
telegram.vendor.ptb_urllib3.urllib3.connectionpool - WARNING - Retrying (Retry(total=2, connect=None, read=None, redirect=None)) after connection broken by 'NewConnectionError('<telegram.vendor.ptb_urllib3.urllib3.contrib.socks.SOCKSHTTPSConnection object at 0x0000000005156A20>: Failed to establish a new connection: [Errno 11001] getaddrinfo failed',)': /bot596268584:AAEbS5S8eJYm3ksbBy3fluXIrgifedC23lg/getUpdates
telegram.vendor.ptb_urllib3.urllib3.connectionpool - WARNING - Retrying (Retry(total=1, connect=None, read=None, redirect=None)) after connection broken by 'NewConnectionError('<telegram.vendor.ptb_urllib3.urllib3.contrib.socks.SOCKSHTTPSConnection object at 0x00000000035CCF98>: Failed to establish a new connection: [Errno 11001] getaddrinfo failed',)': /bot596268584:AAEbS5S8eJYm3ksbBy3fluXIrgifedC23lg/getUpdates
telegram.vendor.ptb_urllib3.urllib3.connectionpool - WARNING - Retrying (Retry(total=0, connect=None, read=None, redirect=None)) after connection broken by 'NewConnectionError('<telegram.vendor.ptb_urllib3.urllib3.contrib.socks.SOCKSHTTPSConnection object at 0x00000000035CC630>: Failed to establish a new connection: [Errno 11001] getaddrinfo failed',)': /bot596268584:AAEbS5S8eJYm3ksbBy3fluXIrgifedC23lg/getUpdates
telegram.ext.updater - ERROR - Error while getting Updates: urllib3 HTTPError SOCKSHTTPSConnectionPool(host='api.telegram.org', port=443): Max retries exceeded with url: /bot596268584:AAEbS5S8eJYm3ksbBy3fluXIrgifedC23lg/getUpdates (Caused by NewConnectionError('<telegram.vendor.ptb_urllib3.urllib3.contrib.socks.SOCKSHTTPSConnection object at 0x00000000035CCDA0>: Failed to establish a new connection: [Errno 11001] getaddrinfo failed',))
telegram.vendor.ptb_urllib3.urllib3.connectionpool - WARNING - Retrying (Retry(total=2, connect=None, read=None, redirect=None)) after connection broken by 'NewConnectionError('<telegram.vendor.ptb_urllib3.urllib3.contrib.socks.SOCKSHTTPSConnection object at 0x0000000005156278>: Failed to establish a new connection: [Errno 11001] getaddrinfo failed',)': /bot596268584:AAEbS5S8eJYm3ksbBy3fluXIrgifedC23lg/getUpdates
telegram.vendor.ptb_urllib3.urllib3.connectionpool - WARNING - Retrying (Retry(total=1, connect=None, read=None, redirect=None)) after connection broken by 'NewConnectionError('<telegram.vendor.ptb_urllib3.urllib3.contrib.socks.SOCKSHTTPSConnection object at 0x00000000035EFE10>: Failed to establish a new connection: [Errno 11001] getaddrinfo failed',)': /bot596268584:AAEbS5S8eJYm3ksbBy3fluXIrgifedC23lg/getUpdates
telegram.vendor.ptb_urllib3.urllib3.connectionpool - WARNING - Retrying (Retry(total=0, connect=None, read=None, redirect=None)) after connection broken by 'NewConnectionError('<telegram.vendor.ptb_urllib3.urllib3.contrib.socks.SOCKSHTTPSConnection object at 0x00000000035EFA58>: Failed to establish a new connection: [Errno 11001] getaddrinfo failed',)': /bot596268584:AAEbS5S8eJYm3ksbBy3fluXIrgifedC23lg/getUpdates
telegram.ext.updater - ERROR - Error while getting Updates: urllib3 HTTPError SOCKSHTTPSConnectionPool(host='api.telegram.org', port=443): Max retries exceeded with url: /bot596268584:AAEbS5S8eJYm3ksbBy3fluXIrgifedC23lg/getUpdates (Caused by NewConnectionError('<telegram.vendor.ptb_urllib3.urllib3.contrib.socks.SOCKSHTTPSConnection object at 0x00000000035EF978>: Failed to establish a new connection: [Errno 11001] getaddrinfo failed',))
telegram.vendor.ptb_urllib3.urllib3.connectionpool - WARNING - Retrying (Retry(total=2, connect=None, read=None, redirect=None)) after connection broken by 'NewConnectionError('<telegram.vendor.ptb_urllib3.urllib3.contrib.socks.SOCKSHTTPSConnection object at 0x0000000005156048>: Failed to establish a new connection: [Errno 11001] getaddrinfo failed',)': /bot596268584:AAEbS5S8eJYm3ksbBy3fluXIrgifedC23lg/getUpdates
telegram.vendor.ptb_urllib3.urllib3.connectionpool - WARNING - Retrying (Retry(total=1, connect=None, read=None, redirect=None)) after connection broken by 'NewConnectionError('<telegram.vendor.ptb_urllib3.urllib3.contrib.socks.SOCKSHTTPSConnection object at 0x0000000005162978>: Failed to establish a new connection: [Errno 11001] getaddrinfo failed',)': /bot596268584:AAEbS5S8eJYm3ksbBy3fluXIrgifedC23lg/getUpdates
telegram.vendor.ptb_urllib3.urllib3.connectionpool - WARNING - Retrying (Retry(total=0, connect=None, read=None, redirect=None)) after connection broken by 'NewConnectionError('<telegram.vendor.ptb_urllib3.urllib3.contrib.socks.SOCKSHTTPSConnection object at 0x0000000005162DD8>: Failed to establish a new connection: [Errno 11001] getaddrinfo failed',)': /bot596268584:AAEbS5S8eJYm3ksbBy3fluXIrgifedC23lg/getUpdates
telegram.ext.updater - ERROR - Error while getting Updates: urllib3 HTTPError SOCKSHTTPSConnectionPool(host='api.telegram.org', port=443): Max retries exceeded with url: /bot596268584:AAEbS5S8eJYm3ksbBy3fluXIrgifedC23lg/getUpdates (Caused by NewConnectionError('<telegram.vendor.ptb_urllib3.urllib3.contrib.socks.SOCKSHTTPSConnection object at 0x0000000006198CC0>: Failed to establish a new connection: [Errno 11001] getaddrinfo failed',))
telegram.vendor.ptb_urllib3.urllib3.connectionpool - WARNING - Retrying (Retry(total=2, connect=None, read=None, redirect=None)) after connection broken by 'NewConnectionError('<telegram.vendor.ptb_urllib3.urllib3.contrib.socks.SOCKSHTTPSConnection object at 0x00000000035CCDA0>: Failed to establish a new connection: [Errno 11001] getaddrinfo failed',)': /bot596268584:AAEbS5S8eJYm3ksbBy3fluXIrgifedC23lg/getUpdates
telegram.vendor.ptb_urllib3.urllib3.connectionpool - WARNING - Retrying (Retry(total=1, connect=None, read=None, redirect=None)) after connection broken by 'NewConnectionError('<telegram.vendor.ptb_urllib3.urllib3.contrib.socks.SOCKSHTTPSConnection object at 0x0000000006198780>: Failed to establish a new connection: [Errno 11001] getaddrinfo failed',)': /bot596268584:AAEbS5S8eJYm3ksbBy3fluXIrgifedC23lg/getUpdates
telegram.vendor.ptb_urllib3.urllib3.connectionpool - WARNING - Retrying (Retry(total=0, connect=None, read=None, redirect=None)) after connection broken by 'NewConnectionError('<telegram.vendor.ptb_urllib3.urllib3.contrib.socks.SOCKSHTTPSConnection object at 0x0000000006198470>: Failed to establish a new connection: [Errno 11001] getaddrinfo failed',)': /bot596268584:AAEbS5S8eJYm3ksbBy3fluXIrgifedC23lg/getUpdates
telegram.ext.updater - ERROR - Error while getting Updates: urllib3 HTTPError SOCKSHTTPSConnectionPool(host='api.telegram.org', port=443): Max retries exceeded with url: /bot596268584:AAEbS5S8eJYm3ksbBy3fluXIrgifedC23lg/getUpdates (Caused by NewConnectionError('<telegram.vendor.ptb_urllib3.urllib3.contrib.socks.SOCKSHTTPSConnection object at 0x0000000004F630F0>: Failed to establish a new connection: [Errno 11001] getaddrinfo failed',))
telegram.vendor.ptb_urllib3.urllib3.connectionpool - WARNING - Retrying (Retry(total=2, connect=None, read=None, redirect=None)) after connection broken by 'NewConnectionError('<telegram.vendor.ptb_urllib3.urllib3.contrib.socks.SOCKSHTTPSConnection object at 0x00000000061987F0>: Failed to establish a new connection: [Errno 11001] getaddrinfo failed',)': /bot596268584:AAEbS5S8eJYm3ksbBy3fluXIrgifedC23lg/getUpdates
telegram.vendor.ptb_urllib3.urllib3.connectionpool - WARNING - Retrying (Retry(total=1, connect=None, read=None, redirect=None)) after connection broken by 'NewConnectionError('<telegram.vendor.ptb_urllib3.urllib3.contrib.socks.SOCKSHTTPSConnection object at 0x0000000004F632B0>: Failed to establish a new connection: [Errno 11001] getaddrinfo failed',)': /bot596268584:AAEbS5S8eJYm3ksbBy3fluXIrgifedC23lg/getUpdates
telegram.vendor.ptb_urllib3.urllib3.connectionpool - WARNING - Retrying (Retry(total=0, connect=None, read=None, redirect=None)) after connection broken by 'NewConnectionError('<telegram.vendor.ptb_urllib3.urllib3.contrib.socks.SOCKSHTTPSConnection object at 0x0000000004F633C8>: Failed to establish a new connection: [Errno 11001] getaddrinfo failed',)': /bot596268584:AAEbS5S8eJYm3ksbBy3fluXIrgifedC23lg/getUpdates
telegram.ext.updater - ERROR - Error while getting Updates: urllib3 HTTPError SOCKSHTTPSConnectionPool(host='api.telegram.org', port=443): Max retries exceeded with url: /bot596268584:AAEbS5S8eJYm3ksbBy3fluXIrgifedC23lg/getUpdates (Caused by NewConnectionError('<telegram.vendor.ptb_urllib3.urllib3.contrib.socks.SOCKSHTTPSConnection object at 0x0000000004F634A8>: Failed to establish a new connection: [Errno 11001] getaddrinfo failed',))
telegram.vendor.ptb_urllib3.urllib3.connectionpool - WARNING - Retrying (Retry(total=2, connect=None, read=None, redirect=None)) after connection broken by 'NewConnectionError('<telegram.vendor.ptb_urllib3.urllib3.contrib.socks.SOCKSHTTPSConnection object at 0x0000000006198198>: Failed to establish a new connection: [Errno 11001] getaddrinfo failed',)': /bot596268584:AAEbS5S8eJYm3ksbBy3fluXIrgifedC23lg/getUpdates
telegram.vendor.ptb_urllib3.urllib3.connectionpool - WARNING - Retrying (Retry(total=1, connect=None, read=None, redirect=None)) after connection broken by 'NewConnectionError('<telegram.vendor.ptb_urllib3.urllib3.contrib.socks.SOCKSHTTPSConnection object at 0x0000000006198208>: Failed to establish a new connection: [Errno 11001] getaddrinfo failed',)': /bot596268584:AAEbS5S8eJYm3ksbBy3fluXIrgifedC23lg/getUpdates
telegram.vendor.ptb_urllib3.urllib3.connectionpool - WARNING - Retrying (Retry(total=0, connect=None, read=None, redirect=None)) after connection broken by 'NewConnectionError('<telegram.vendor.ptb_urllib3.urllib3.contrib.socks.SOCKSHTTPSConnection object at 0x0000000006198358>: Failed to establish a new connection: [Errno 11001] getaddrinfo failed',)': /bot596268584:AAEbS5S8eJYm3ksbBy3fluXIrgifedC23lg/getUpdates
telegram.ext.updater - ERROR - Error while getting Updates: urllib3 HTTPError SOCKSHTTPSConnectionPool(host='api.telegram.org', port=443): Max retries exceeded with url: /bot596268584:AAEbS5S8eJYm3ksbBy3fluXIrgifedC23lg/getUpdates (Caused by NewConnectionError('<telegram.vendor.ptb_urllib3.urllib3.contrib.socks.SOCKSHTTPSConnection object at 0x00000000061986D8>: Failed to establish a new connection: [Errno 11001] getaddrinfo failed',))
telegram.vendor.ptb_urllib3.urllib3.connectionpool - WARNING - Retrying (Retry(total=2, connect=None, read=None, redirect=None)) after connection broken by 'NewConnectionError('<telegram.vendor.ptb_urllib3.urllib3.contrib.socks.SOCKSHTTPSConnection object at 0x0000000006198E10>: Failed to establish a new connection: [Errno 11001] getaddrinfo failed',)': /bot596268584:AAEbS5S8eJYm3ksbBy3fluXIrgifedC23lg/getUpdates
telegram.vendor.ptb_urllib3.urllib3.connectionpool - WARNING - Retrying (Retry(total=1, connect=None, read=None, redirect=None)) after connection broken by 'NewConnectionError('<telegram.vendor.ptb_urllib3.urllib3.contrib.socks.SOCKSHTTPSConnection object at 0x00000000051562E8>: Failed to establish a new connection: [Errno 11001] getaddrinfo failed',)': /bot596268584:AAEbS5S8eJYm3ksbBy3fluXIrgifedC23lg/getUpdates
telegram.vendor.ptb_urllib3.urllib3.connectionpool - WARNING - Retrying (Retry(total=0, connect=None, read=None, redirect=None)) after connection broken by 'NewConnectionError('<telegram.vendor.ptb_urllib3.urllib3.contrib.socks.SOCKSHTTPSConnection object at 0x00000000051566A0>: Failed to establish a new connection: [Errno 11001] getaddrinfo failed',)': /bot596268584:AAEbS5S8eJYm3ksbBy3fluXIrgifedC23lg/getUpdates
telegram.ext.updater - ERROR - Error while getting Updates: urllib3 HTTPError SOCKSHTTPSConnectionPool(host='api.telegram.org', port=443): Max retries exceeded with url: /bot596268584:AAEbS5S8eJYm3ksbBy3fluXIrgifedC23lg/getUpdates (Caused by NewConnectionError('<telegram.vendor.ptb_urllib3.urllib3.contrib.socks.SOCKSHTTPSConnection object at 0x0000000005156E80>: Failed to establish a new connection: [Errno 11001] getaddrinfo failed',))
telegram.vendor.ptb_urllib3.urllib3.connectionpool - WARNING - Retrying (Retry(total=2, connect=None, read=None, redirect=None)) after connection broken by 'NewConnectionError('<telegram.vendor.ptb_urllib3.urllib3.contrib.socks.SOCKSHTTPSConnection object at 0x0000000006198240>: Failed to establish a new connection: [Errno 11001] getaddrinfo failed',)': /bot596268584:AAEbS5S8eJYm3ksbBy3fluXIrgifedC23lg/getUpdates
telegram.vendor.ptb_urllib3.urllib3.connectionpool - WARNING - Retrying (Retry(total=1, connect=None, read=None, redirect=None)) after connection broken by 'NewConnectionError('<telegram.vendor.ptb_urllib3.urllib3.contrib.socks.SOCKSHTTPSConnection object at 0x0000000005156F98>: Failed to establish a new connection: [Errno 11001] getaddrinfo failed',)': /bot596268584:AAEbS5S8eJYm3ksbBy3fluXIrgifedC23lg/getUpdates
telegram.vendor.ptb_urllib3.urllib3.connectionpool - WARNING - Retrying (Retry(total=0, connect=None, read=None, redirect=None)) after connection broken by 'NewConnectionError('<telegram.vendor.ptb_urllib3.urllib3.contrib.socks.SOCKSHTTPSConnection object at 0x0000000005156208>: Failed to establish a new connection: [Errno 11001] getaddrinfo failed',)': /bot596268584:AAEbS5S8eJYm3ksbBy3fluXIrgifedC23lg/getUpdates
telegram.ext.updater - ERROR - Error while getting Updates: urllib3 HTTPError SOCKSHTTPSConnectionPool(host='api.telegram.org', port=443): Max retries exceeded with url: /bot596268584:AAEbS5S8eJYm3ksbBy3fluXIrgifedC23lg/getUpdates (Caused by NewConnectionError('<telegram.vendor.ptb_urllib3.urllib3.contrib.socks.SOCKSHTTPSConnection object at 0x0000000005156160>: Failed to establish a new connection: [Errno 11001] getaddrinfo failed',))
telegram.ext.updater - INFO - Received signal 2 (SIGINT), stopping...
telegram.ext.dispatcher - ERROR - An uncaught error was raised while processing the update
Traceback (most recent call last):
  File "C:\Python34\lib\site-packages\telegram\ext\dispatcher.py", line 279, in process_update
    handler.handle_update(update, self)
  File "C:\Python34\lib\site-packages\telegram\ext\commandhandler.py", line 173, in handle_update
    return self.callback(dispatcher.bot, update, **optional_args)
  File "calc.py", line 87, in calc
    update.message.reply_text("Результат: "+str(val))
UnboundLocalError: local variable 'val' referenced before assignment
telegram.ext.updater - INFO - Received signal 2 (SIGINT), stopping...
